Workbook

Sheet Account Manager Data
A1: AM | B1: AM_Name | C1: area_id | D1: Postion
A2: AM001 | B2: Rizky Maulana | C2: Jawa | D2: 1
A3: AM002 | B3: Dedi Kurniawan | C3: Kalimantan | D3: 1
A4: AM003 | B4: Ahmad Fauzi | C4: Sumatera | D4: 1
A5: AM004 | B5: Eko Prasetyo | C5: Papua | D5: 1
A6: AM005 | B6: Fajar Ramadhan | C6: Sulawesi | D6: 1
A7: AM006 | B7: Hendra Gunawan | C7: Kalimantan | D7: 1
A8: AM007 | B8: Yusuf Hidayat | C8: Sumatera | D8: 2
A9: AM008 | B9: Budi Santoso | C9: Papua | D9: 2
A10: AM009 | B10: Teguh Wijaya | C10: Sulawesi | D10: 2
A11: AM010 | B11: Ilham Saputra | C11: Jawa | D11: 2

Sheet Target
I1: Achivement 2025 | X1: Target 2026
A2: Region | B2: Position | C2: AM | D2: Jan | E2: Feb | F2: Mar | G2: Apr | H2: Mei | I2: Jun | J2: Jul | K2: Aug | L2: Sep | M2: Oct | N2: Nov | O2: Dec | P2: FY | Q2: Jan | R2: Feb | S2: Mar | T2: Apr | U2: Mei | V2: Jun | W2: Jul | X2: Aug | Y2: Sep | Z2: Oct | AA2: Nov | AB2: Dec | AC2: FY
A3: {=XLOOKUP(C:C,'Account Manager Data'!B:B,'Account Manager Data'!C:C)} -> Jawa | B3: {=XLOOKUP(C3,'Account Manager Data'!$B:$B,'Account Manager Data'!$D:$D)} -> 1 | C3: ='Account Manager Data'!B2 -> Rizky Maulana | D3: 80000000 | E3: 82400000 | F3: 91464000 | G3: 105183600 | H3: 122012976 | I3: 1.4519544e+08 | J3: 1.7350855e+08 | K3: 2.1168043e+08 | L3: 2.6460054e+08 | M3: 3.3154448e+08 | N3: 4.6416227e+08 | O3: 5.8020284e+08 | P3: =SUM(D3:O3) -> 2651955138 | Q3: =SUMIFS(D29:D30,$B$29:$B$30,$B$3) -> 55696074 | R3: =SUMIFS($E$29:$E$30,$B$29:$B$30,B3) -> 69620093 | S3: =SUMIFS($F$29:$F$30,$B$29:$B$30,B3) -> 83544111 | T3: =SUMIFS($G$29:$G$30,$B$29:$B$30,B3) -> 97468130 | U3: =SUMIFS($H$29:$H$30,$B$29:$B$30,B3) -> 1.1139215e+08 | V3: =SUMIFS($I$29:$I$30,$B$29:$B$30,B3) -> 125316167 | W3: =SUMIFS($J$29:$J$30,$B$29:$B$30,B3) -> 125316167 | X3: =SUMIFS($K$29:$K$30,$B$29:$B$30,B3) -> 125316167 | Y3: =SUMIFS($L$29:$L$30,$B$29:$B$30,B3) -> 1.3924019e+08 | Z3: =SUMIFS($M$29:$M$30,$B$29:$B$30,B3) -> 1.3924019e+08 | AA3: =SUMIFS($N$29:$N$30,$B$29:$B$30,B3) -> 1.531642e+08 | AB3: =SUMIFS($O$29:$O$30,$B$29:$B$30,B3) -> 1.6708822e+08 | AC3: =SUM(Q3:AB3) -> 1392401856
A4: {=XLOOKUP(C:C,'Account Manager Data'!B:B,'Account Manager Data'!C:C)} -> Kalimantan | B4: {=XLOOKUP(C4,'Account Manager Data'!$B:$B,'Account Manager Data'!$D:$D)} -> 1 | C4: ='Account Manager Data'!B3 -> Dedi Kurniawan | D4: 50000000 | E4: 51500000 | F4: 55620000 | G4: 61182000 | H4: 68523840 | I4: 78802416 | J4: 94168887 | K4: 1.1394435e+08 | L4: 1.3901211e+08 | M4: 1.7237502e+08 | N4: 2.1495165e+08 | O4: 2.6868956e+08 | P4: =SUM(D4:O4) -> 1368769832 | Q4: =SUMIFS($D$29:$D$30,$B$29:$B$30,B4) -> 55696074 | R4: =SUMIFS($E$29:$E$30,$B$29:$B$30,B4) -> 69620093 | S4: =SUMIFS($F$29:$F$30,$B$29:$B$30,B4) -> 83544111 | T4: =SUMIFS($G$29:$G$30,$B$29:$B$30,B4) -> 97468130 | U4: =SUMIFS($H$29:$H$30,$B$29:$B$30,B4) -> 1.1139215e+08 | V4: =SUMIFS($I$29:$I$30,$B$29:$B$30,B4) -> 125316167 | W4: =SUMIFS($J$29:$J$30,$B$29:$B$30,B4) -> 125316167 | X4: =SUMIFS($K$29:$K$30,$B$29:$B$30,B4) -> 125316167 | Y4: =SUMIFS($L$29:$L$30,$B$29:$B$30,B4) -> 1.3924019e+08 | Z4: =SUMIFS($M$29:$M$30,$B$29:$B$30,B4) -> 1.3924019e+08 | AA4: =SUMIFS($N$29:$N$30,$B$29:$B$30,B4) -> 1.531642e+08 | AB4: =SUMIFS($O$29:$O$30,$B$29:$B$30,B4) -> 1.6708822e+08 | AC4: =SUM(Q4:AB4) -> 1392401856
A5: {=XLOOKUP(C:C,'Account Manager Data'!B:B,'Account Manager Data'!C:C)} -> Sumatera | B5: {=XLOOKUP(C5,'Account Manager Data'!$B:$B,'Account Manager Data'!$D:$D)} -> 1 | C5: ='Account Manager Data'!B4 -> Ahmad Fauzi | D5: 45000000 | E5: 46350000 | F5: 48667500 | G5: 52074225 | H5: 56240163 | I5: 61864179 | J5: 68978560 | K5: 77255987 | L5: 88844385 | M5: 1.0305949e+08 | N5: 1.210949e+08 | O5: 1.4410293e+08 | P5: =SUM(D5:O5) -> 9.1353231e+08 | Q5: =SUMIFS($D$29:$D$30,$B$29:$B$30,B5) -> 55696074 | R5: =SUMIFS($E$29:$E$30,$B$29:$B$30,B5) -> 69620093 | S5: =SUMIFS($F$29:$F$30,$B$29:$B$30,B5) -> 83544111 | T5: =SUMIFS($G$29:$G$30,$B$29:$B$30,B5) -> 97468130 | U5: =SUMIFS($H$29:$H$30,$B$29:$B$30,B5) -> 1.1139215e+08 | V5: =SUMIFS($I$29:$I$30,$B$29:$B$30,B5) -> 125316167 | W5: =SUMIFS($J$29:$J$30,$B$29:$B$30,B5) -> 125316167 | X5: =SUMIFS($K$29:$K$30,$B$29:$B$30,B5) -> 125316167 | Y5: =SUMIFS($L$29:$L$30,$B$29:$B$30,B5) -> 1.3924019e+08 | Z5: =SUMIFS($M$29:$M$30,$B$29:$B$30,B5) -> 1.3924019e+08 | AA5: =SUMIFS($N$29:$N$30,$B$29:$B$30,B5) -> 1.531642e+08 | AB5: =SUMIFS($O$29:$O$30,$B$29:$B$30,B5) -> 1.6708822e+08 | AC5: =SUM(Q5:AB5) -> 1392401856
A6: {=XLOOKUP(C:C,'Account Manager Data'!B:B,'Account Manager Data'!C:C)} -> Papua | B6: {=XLOOKUP(C6,'Account Manager Data'!$B:$B,'Account Manager Data'!$D:$D)} -> 1 | C6: ='Account Manager Data'!B5 -> Eko Prasetyo | D6: 60000000 | E6: 66000000 | F6: 76560000 | G6: 89575200 | H6: 104355108 | I6: 1.2418258e+08 | J6: 1.4653544e+08 | K6: 1.7510985e+08 | L6: 2.1013182e+08 | M6: 2.5636083e+08 | N6: 2.8584232e+08 | O6: 3.7159502e+08 | P6: =SUM(D6:O6) -> 1966248173 | Q6: =SUMIFS($D$29:$D$30,$B$29:$B$30,B6) -> 55696074 | R6: =SUMIFS($E$29:$E$30,$B$29:$B$30,B6) -> 69620093 | S6: =SUMIFS($F$29:$F$30,$B$29:$B$30,B6) -> 83544111 | T6: =SUMIFS($G$29:$G$30,$B$29:$B$30,B6) -> 97468130 | U6: =SUMIFS($H$29:$H$30,$B$29:$B$30,B6) -> 1.1139215e+08 | V6: =SUMIFS($I$29:$I$30,$B$29:$B$30,B6) -> 125316167 | W6: =SUMIFS($J$29:$J$30,$B$29:$B$30,B6) -> 125316167 | X6: =SUMIFS($K$29:$K$30,$B$29:$B$30,B6) -> 125316167 | Y6: =SUMIFS($L$29:$L$30,$B$29:$B$30,B6) -> 1.3924019e+08 | Z6: =SUMIFS($M$29:$M$30,$B$29:$B$30,B6) -> 1.3924019e+08 | AA6: =SUMIFS($N$29:$N$30,$B$29:$B$30,B6) -> 1.531642e+08 | AB6: =SUMIFS($O$29:$O$30,$B$29:$B$30,B6) -> 1.6708822e+08 | AC6: =SUM(Q6:AB6) -> 1392401856
A7: {=XLOOKUP(C:C,'Account Manager Data'!B:B,'Account Manager Data'!C:C)} -> Sulawesi | B7: {=XLOOKUP(C7,'Account Manager Data'!$B:$B,'Account Manager Data'!$D:$D)} -> 1 | C7: ='Account Manager Data'!B6 -> Fajar Ramadhan | D7: 40000000 | E7: 43600000 | F7: 48396000 | G7: 54203520 | H7: 61249978 | I7: 69824974 | J7: 80298721 | K7: 93146516 | L7: 1.0991289e+08 | M7: 1.3189547e+08 | N7: 1.5893404e+08 | O7: 1.9072084e+08 | P7: =SUM(D7:O7) -> 1082182946 | Q7: =SUMIFS($D$29:$D$30,$B$29:$B$30,B7) -> 55696074 | R7: =SUMIFS($E$29:$E$30,$B$29:$B$30,B7) -> 69620093 | S7: =SUMIFS($F$29:$F$30,$B$29:$B$30,B7) -> 83544111 | T7: =SUMIFS($G$29:$G$30,$B$29:$B$30,B7) -> 97468130 | U7: =SUMIFS($H$29:$H$30,$B$29:$B$30,B7) -> 1.1139215e+08 | V7: =SUMIFS($I$29:$I$30,$B$29:$B$30,B7) -> 125316167 | W7: =SUMIFS($J$29:$J$30,$B$29:$B$30,B7) -> 125316167 | X7: =SUMIFS($K$29:$K$30,$B$29:$B$30,B7) -> 125316167 | Y7: =SUMIFS($L$29:$L$30,$B$29:$B$30,B7) -> 1.3924019e+08 | Z7: =SUMIFS($M$29:$M$30,$B$29:$B$30,B7) -> 1.3924019e+08 | AA7: =SUMIFS($N$29:$N$30,$B$29:$B$30,B7) -> 1.531642e+08 | AB7: =SUMIFS($O$29:$O$30,$B$29:$B$30,B7) -> 1.6708822e+08 | AC7: =SUM(Q7:AB7) -> 1392401856
A8: {=XLOOKUP(C:C,'Account Manager Data'!B:B,'Account Manager Data'!C:C)} -> Kalimantan | B8: {=XLOOKUP(C8,'Account Manager Data'!$B:$B,'Account Manager Data'!$D:$D)} -> 1 | C8: ='Account Manager Data'!B7 -> Hendra Gunawan | D8: 25000000 | E8: 25500000 | F8: 26265000 | G8: 27052950 | H8: 28270333 | I8: 29683849 | J8: 31019623 | K8: 32880800 | L8: 35840072 | M8: 37632076 | N8: 38761038 | O8: 39536259 | P8: =SUM(D8:O8) -> 3.77442e+08 | Q8: =SUMIFS($D$29:$D$30,$B$29:$B$30,B8) -> 55696074 | R8: =SUMIFS($E$29:$E$30,$B$29:$B$30,B8) -> 69620093 | S8: =SUMIFS($F$29:$F$30,$B$29:$B$30,B8) -> 83544111 | T8: =SUMIFS($G$29:$G$30,$B$29:$B$30,B8) -> 97468130 | U8: =SUMIFS($H$29:$H$30,$B$29:$B$30,B8) -> 1.1139215e+08 | V8: =SUMIFS($I$29:$I$30,$B$29:$B$30,B8) -> 125316167 | W8: =SUMIFS($J$29:$J$30,$B$29:$B$30,B8) -> 125316167 | X8: =SUMIFS($K$29:$K$30,$B$29:$B$30,B8) -> 125316167 | Y8: =SUMIFS($L$29:$L$30,$B$29:$B$30,B8) -> 1.3924019e+08 | Z8: =SUMIFS($M$29:$M$30,$B$29:$B$30,B8) -> 1.3924019e+08 | AA8: =SUMIFS($N$29:$N$30,$B$29:$B$30,B8) -> 1.531642e+08 | AB8: =SUMIFS($O$29:$O$30,$B$29:$B$30,B8) -> 1.6708822e+08 | AC8: =SUM(Q8:AB8) -> 1392401856
A9: {=XLOOKUP(C:C,'Account Manager Data'!B:B,'Account Manager Data'!C:C)} -> Sumatera | B9: {=XLOOKUP(C9,'Account Manager Data'!$B:$B,'Account Manager Data'!$D:$D)} -> 2 | C9: ='Account Manager Data'!B8 -> Yusuf Hidayat | D9: 27000000 | E9: 27540000 | F9: 28366200 | G9: 29217186 | H9: 30531959 | I9: 32058557 | J9: 33501192 | K9: 35511264 | L9: 38707278 | M9: 40642642 | N9: 41861921 | O9: 42699159 | P9: =SUM(D9:O9) -> 4.0763736e+08 | Q9: =SUMIFS($D$29:$D$30,$B$29:$B$30,B9) -> 27848037 | R9: =SUMIFS($E$29:$E$30,$B$29:$B$30,B9) -> 34810046 | S9: =SUMIFS($F$29:$F$30,$B$29:$B$30,B9) -> 41772056 | T9: =SUMIFS($G$29:$G$30,$B$29:$B$30,B9) -> 48734065 | U9: =SUMIFS($H$29:$H$30,$B$29:$B$30,B9) -> 55696074 | V9: =SUMIFS($I$29:$I$30,$B$29:$B$30,B9) -> 62658084 | W9: =SUMIFS($J$29:$J$30,$B$29:$B$30,B9) -> 62658084 | X9: =SUMIFS($K$29:$K$30,$B$29:$B$30,B9) -> 62658084 | Y9: =SUMIFS($L$29:$L$30,$B$29:$B$30,B9) -> 69620093 | Z9: =SUMIFS($M$29:$M$30,$B$29:$B$30,B9) -> 69620093 | AA9: =SUMIFS($N$29:$N$30,$B$29:$B$30,B9) -> 76582102 | AB9: =SUMIFS($O$29:$O$30,$B$29:$B$30,B9) -> 83544111 | AC9: =SUM(Q9:AB9) -> 6.9620093e+08
A10: {=XLOOKUP(C:C,'Account Manager Data'!B:B,'Account Manager Data'!C:C)} -> Papua | B10: {=XLOOKUP(C10,'Account Manager Data'!$B:$B,'Account Manager Data'!$D:$D)} -> 2 | C10: ='Account Manager Data'!B9 -> Budi Santoso | D10: 30000000 | E10: 30600000 | F10: 31518000 | G10: 32463540 | H10: 33924399 | I10: 35620619 | J10: 37223547 | K10: 39456960 | L10: 43008086 | M10: 45158491 | N10: 46513245 | O10: 47443510 | P10: =SUM(D10:O10) -> 4.529304e+08 | Q10: =SUMIFS($D$29:$D$30,$B$29:$B$30,B10) -> 27848037 | R10: =SUMIFS($E$29:$E$30,$B$29:$B$30,B10) -> 34810046 | S10: =SUMIFS($F$29:$F$30,$B$29:$B$30,B10) -> 41772056 | T10: =SUMIFS($G$29:$G$30,$B$29:$B$30,B10) -> 48734065 | U10: =SUMIFS($H$29:$H$30,$B$29:$B$30,B10) -> 55696074 | V10: =SUMIFS($I$29:$I$30,$B$29:$B$30,B10) -> 62658084 | W10: =SUMIFS($J$29:$J$30,$B$29:$B$30,B10) -> 62658084 | X10: =SUMIFS($K$29:$K$30,$B$29:$B$30,B10) -> 62658084 | Y10: =SUMIFS($L$29:$L$30,$B$29:$B$30,B10) -> 69620093 | Z10: =SUMIFS($M$29:$M$30,$B$29:$B$30,B10) -> 69620093 | AA10: =SUMIFS($N$29:$N$30,$B$29:$B$30,B10) -> 76582102 | AB10: =SUMIFS($O$29:$O$30,$B$29:$B$30,B10) -> 83544111 | AC10: =SUM(Q10:AB10) -> 6.9620093e+08
A11: {=XLOOKUP(C:C,'Account Manager Data'!B:B,'Account Manager Data'!C:C)} -> Sulawesi | B11: {=XLOOKUP(C11,'Account Manager Data'!$B:$B,'Account Manager Data'!$D:$D)} -> 2 | C11: ='Account Manager Data'!B10 -> Teguh Wijaya | D11: 20000000 | E11: 20400000 | F11: 21012000 | G11: 21642360 | H11: 22616266 | I11: 23747080 | J11: 24815698 | K11: 26304640 | L11: 28672058 | M11: 30105660 | N11: 31008830 | O11: 31629007 | P11: =SUM(D11:O11) -> 3.019536e+08 | Q11: =SUMIFS($D$29:$D$30,$B$29:$B$30,B11) -> 27848037 | R11: =SUMIFS($E$29:$E$30,$B$29:$B$30,B11) -> 34810046 | S11: =SUMIFS($F$29:$F$30,$B$29:$B$30,B11) -> 41772056 | T11: =SUMIFS($G$29:$G$30,$B$29:$B$30,B11) -> 48734065 | U11: =SUMIFS($H$29:$H$30,$B$29:$B$30,B11) -> 55696074 | V11: =SUMIFS($I$29:$I$30,$B$29:$B$30,B11) -> 62658084 | W11: =SUMIFS($J$29:$J$30,$B$29:$B$30,B11) -> 62658084 | X11: =SUMIFS($K$29:$K$30,$B$29:$B$30,B11) -> 62658084 | Y11: =SUMIFS($L$29:$L$30,$B$29:$B$30,B11) -> 69620093 | Z11: =SUMIFS($M$29:$M$30,$B$29:$B$30,B11) -> 69620093 | AA11: =SUMIFS($N$29:$N$30,$B$29:$B$30,B11) -> 76582102 | AB11: =SUMIFS($O$29:$O$30,$B$29:$B$30,B11) -> 83544111 | AC11: =SUM(Q11:AB11) -> 6.9620093e+08
A12: {=XLOOKUP(C:C,'Account Manager Data'!B:B,'Account Manager Data'!C:C)} -> Jawa | B12: {=XLOOKUP(C12,'Account Manager Data'!$B:$B,'Account Manager Data'!$D:$D)} -> 2 | C12: ='Account Manager Data'!B11 -> Ilham Saputra | D12: 40000000 | E12: 40800000 | F12: 42024000 | G12: 43284720 | H12: 45232532 | I12: 47494159 | J12: 49631396 | K12: 52609280 | L12: 57344115 | M12: 60211321 | N12: 62017661 | O12: 63258014 | P12: =SUM(D12:O12) -> 6.039072e+08 | Q12: =SUMIFS($D$29:$D$30,$B$29:$B$30,B12) -> 27848037 | R12: =SUMIFS($E$29:$E$30,$B$29:$B$30,B12) -> 34810046 | S12: =SUMIFS($F$29:$F$30,$B$29:$B$30,B12) -> 41772056 | T12: =SUMIFS($G$29:$G$30,$B$29:$B$30,B12) -> 48734065 | U12: =SUMIFS($H$29:$H$30,$B$29:$B$30,B12) -> 55696074 | V12: =SUMIFS($I$29:$I$30,$B$29:$B$30,B12) -> 62658084 | W12: =SUMIFS($J$29:$J$30,$B$29:$B$30,B12) -> 62658084 | X12: =SUMIFS($K$29:$K$30,$B$29:$B$30,B12) -> 62658084 | Y12: =SUMIFS($L$29:$L$30,$B$29:$B$30,B12) -> 69620093 | Z12: =SUMIFS($M$29:$M$30,$B$29:$B$30,B12) -> 69620093 | AA12: =SUMIFS($N$29:$N$30,$B$29:$B$30,B12) -> 76582102 | AB12: =SUMIFS($O$29:$O$30,$B$29:$B$30,B12) -> 83544111 | AC12: =SUM(Q12:AB12) -> 6.9620093e+08
A13: Total | D13: =SUM(D1:D12) -> 417000000 | E13: =SUM(E1:E12) -> 434690000 | F13: =SUM(F1:F12) -> 469892700 | G13: =SUM(G1:G12) -> 515879301 | H13: =SUM(H1:H12) -> 5.7295755e+08 | I13: =SUM(I1:I12) -> 6.4847385e+08 | J13: =SUM(J1:J12) -> 7.3968162e+08 | K13: =SUM(K1:K12) -> 8.5790009e+08 | ... O13: =SUM(O1:O12) -> 1779877137 | P13: =SUM(P3:P12) -> 10126558952 | Q13: =SUM(Q3:Q12) -> 4.4556859e+08 | R13: =SUM(R3:R12) -> 5.5696074e+08 | S13: =SUM(S3:S12) -> 6.6835289e+08 | T13: =SUM(T3:T12) -> 7.7974504e+08 | U13: =SUM(U3:U12) -> 8.9113719e+08 | V13: =SUM(V3:V12) -> 1002529336 | W13: =SUM(W3:W12) -> 1002529336 | ... AB13: =SUM(AB3:AB12) -> 1336705782 | AC13: 1.1139215e+10
A16: Target 2026
A17: Revenue 25 | C17: =P13 -> 10126558952
A18: Growth | C18: 0.1 | D18: =C17*C18 -> 1012655895 | P18: -
A19: Target 26 | C19: =D18+C17 -> 11139214847
A21: Target 2026 | D21: Jan | E21: Feb | F21: Mar | G21: Apr | H21: Mei | I21: Jun | J21: Jul | K21: Aug | L21: Sep | M21: Oct | N21: Nov | O21: Dec | P21: FY
A22: Postion | B22: Level | C22: Weighting | D22: 0.04 | E22: 0.05 | F22: 0.06 | G22: 0.07 | H22: 0.08 | I22: 0.09 | J22: 0.09 | K22: 0.09 | L22: 0.1 | M22: 0.1 | N22: 0.11 | O22: 0.12 | P22: =SUM(D22:O22) -> 1
A23: Senior | B23: 1 | C23: 0.75 | D23: =$C$23*D25 -> 3.3417645e+08 | E23: =$C$23*E25 -> 4.1772056e+08 | F23: =$C$23*F25 -> 5.0126467e+08 | G23: =$C$23*G25 -> 5.8480878e+08 | H23: =$C$23*H25 -> 6.6835289e+08 | I23: =$C$23*I25 -> 7.51897e+08 | J23: =$C$23*J25 -> 7.51897e+08 | K23: =$C$23*K25 -> 7.51897e+08 | ... O23: =$C$23*O25 -> 1002529336 | P23: =SUM(B23:O23) -> 8354411137
A24: Junior | B24: 2 | C24: 0.25 | D24: =$C$24*D25 -> 1.1139215e+08 | E24: =$C$24*E25 -> 1.3924019e+08 | F24: =$C$24*F25 -> 1.6708822e+08 | G24: =$C$24*G25 -> 1.9493626e+08 | H24: =$C$24*H25 -> 2.227843e+08 | I24: =$C$24*I25 -> 2.5063233e+08 | J24: =$C$24*J25 -> 2.5063233e+08 | K24: =$C$24*K25 -> 2.5063233e+08 | ... O24: =$C$24*O25 -> 3.3417645e+08 | P24: =SUM(B24:O24) -> 2784803714
A25: Total | C25: =C23+C24 -> 1 | D25: =$AC$13*D22 -> 4.4556859e+08 | E25: =$AC$13*E22 -> 5.5696074e+08 | F25: =$AC$13*F22 -> 6.6835289e+08 | G25: =$AC$13*G22 -> 7.7974504e+08 | H25: =$AC$13*H22 -> 8.9113719e+08 | I25: =$AC$13*I22 -> 1002529336 | J25: =$AC$13*J22 -> 1002529336 | K25: =$AC$13*K22 -> 1002529336 | ... O25: =$AC$13*O22 -> 1336705782 | P25: =SUM(D25:O25) -> 11139214847
A28: Target 2026 | B28: Level | C28: Total Employee | D28: Jan | E28: Feb | F28: Mar | G28: Apr | H28: Mei | I28: Jun | J28: Jul | K28: Aug | L28: Sep | M28: Oct | N28: Nov | O28: Dec | P28: FY
A29: Senior | B29: 1 | C29: 6 | D29: =D23/6 -> 55696074 | E29: =E23/6 -> 69620093 | F29: =F23/6 -> 83544111 | G29: =G23/6 -> 97468130 | H29: =H23/6 -> 1.1139215e+08 | I29: =I23/6 -> 125316167 | J29: =J23/6 -> 125316167 | K29: =K23/6 -> 125316167 | ... O29: =O23/6 -> 1.6708822e+08 | P29: =SUM(B29:O29) -> 1392401863
A30: Junior | B30: 2 | C30: 4 | D30: =D24/4 -> 27848037 | E30: =E24/4 -> 34810046 | F30: =F24/4 -> 41772056 | G30: =G24/4 -> 48734065 | H30: =H24/4 -> 55696074 | I30: =I24/4 -> 62658084 | J30: =J24/4 -> 62658084 | K30: =K24/4 -> 62658084 | ... O30: =O24/4 -> 83544111 | P30: =SUM(B30:O30) -> 6.9620093e+08
A31: Total | C31: =C29+C30 -> 10 | P31: =SUM(D31:O31) -> 0

Sheet Raw Revenue
A1: p_id_jan | B1: revenue_jan | C1: p_id_feb | D1: revenue_feb | E1: p_id_mar | F1: revenue_mar | G1: p_id_apr | H1: revenue_apr | I1: p_id_may | J1: revenue_may | K1: p_id_jun | L1: revenue_jun | M1: p_id_jul | N1: revenue_jul | O1: p_id_aug | P1: revenue_aug | Q1: p_id_sep | R1: revenue_sep | S1: p_id_oct | T1: revenue_oct | U1: p_id_nov | V1: revenue_nov | W1: p_id_dec | X1: revenue_dec
A2: PRJ00162 | B2: 7000000 | C2: PRJ00162 | D2: 8470588 | E2: PRJ00162 | F2: 3036145 | G2: PRJ00162 | H2: 1714286 | I2: PRJ00162 | J2: 1281690 | K2: PRJ00162 | L2: 4290650 | M2: PRJ00162 | N2: 30172414 | O2: PRJ00162 | Q2: PRJ00162 | S2: PRJ00162 | U2: PRJ00162 | W2: PRJ00162
A3: PRJ00192 | B3: 2800000 | C3: PRJ00192 | D3: 5647059 | E3: PRJ00192 | F3: 6072289 | G3: PRJ00192 | H3: 10285714 | I3: PRJ00192 | J3: 6408451 | K3: PRJ00192 | L3: 14953236 | M3: PRJ00192 | N3: 8620690 | O3: PRJ00192 | Q3: PRJ00192 | S3: PRJ00192 | U3: PRJ00192 | W3: PRJ00192
A4: PRJ00202 | B4: 6300000 | C4: PRJ00202 | D4: 8470588 | E4: PRJ00202 | F4: 9108434 | G4: PRJ00202 | H4: 5142857 | I4: PRJ00202 | J4: 7690141 | K4: PRJ00202 | L4: 3817905 | M4: PRJ00202 | N4: 38793103 | O4: PRJ00202 | Q4: PRJ00202 | S4: PRJ00202 | U4: PRJ00202 | W4: PRJ00202
A5: PRJ00252 | B5: 700000 | C5: PRJ00252 | D5: 5647059 | E5: PRJ00252 | F5: 6072289 | G5: PRJ00252 | H5: 5142857 | I5: PRJ00252 | J5: 2563380 | K5: PRJ00252 | L5: 1214584 | M5: PRJ00252 | N5: 21551724 | O5: PRJ00252 | Q5: PRJ00252 | S5: PRJ00252 | U5: PRJ00252 | W5: PRJ00252
A6: PRJ00302 | B6: 4200000 | C6: PRJ00302 | D6: 9411765 | E6: PRJ00302 | F6: 3036145 | G6: PRJ00302 | H6: 1714286 | I6: PRJ00302 | J6: 2563380 | K6: PRJ00302 | L6: 1453277 | M6: PRJ00302 | N6: 0 | O6: PRJ00302 | Q6: PRJ00302 | S6: PRJ00302 | U6: PRJ00302 | W6: PRJ00302
A7: PRJ00372 | B7: 7000000 | C7: PRJ00372 | D7: 9411765 | E7: PRJ00372 | F7: 4048193 | G7: PRJ00372 | H7: 1714286 | I7: PRJ00372 | J7: 7690141 | K7: PRJ00372 | L7: 13499019 | M7: PRJ00372 | N7: 4310345 | O7: PRJ00372 | Q7: PRJ00372 | S7: PRJ00372 | U7: PRJ00372 | W7: PRJ00372
A8: PRJ00422 | B8: 1400000 | C8: PRJ00422 | D8: 9411765 | E8: PRJ00422 | F8: 9108434 | G8: PRJ00422 | H8: 5142857 | I8: PRJ00422 | J8: 7690141 | K8: PRJ00422 | L8: 5193569 | M8: PRJ00422 | N8: 0 | O8: PRJ00422 | Q8: PRJ00422 | S8: PRJ00422 | U8: PRJ00422 | W8: PRJ00422
A9: PRJ00432 | B9: 5600000 | C9: PRJ00432 | D9: 941176 | E9: PRJ00432 | F9: 4048193 | G9: PRJ00432 | H9: 1714286 | I9: PRJ00432 | J9: 10253521 | K9: PRJ00432 | L9: 2488250 | M9: PRJ00432 | N9: 43103448 | O9: PRJ00432 | Q9: PRJ00432 | S9: PRJ00432 | U9: PRJ00432 | W9: PRJ00432
A10: PRJ00502 | B10: 4900000 | C10: PRJ00502 | D10: 7529412 | E10: PRJ00502 | F10: 6072289 | G10: PRJ00502 | H10: 3428571 | I10: PRJ00502 | J10: 12816901 | K10: PRJ00502 | L10: 11944937 | M10: PRJ00502 | N10: 30172414 | O10: PRJ00502 | Q10: PRJ00502 | S10: PRJ00502 | U10: PRJ00502 | W10: PRJ00502
A11: PRJ00522 | B11: 4200000 | C11: PRJ00522 | D11: 5647059 | E11: PRJ00522 | F11: 9108434 | G11: PRJ00522 | H11: 12000000 | I11: PRJ00522 | J11: 11535211 | K11: PRJ00522 | L11: 13824614 | M11: PRJ00522 | N11: 43103448 | O11: PRJ00522 | Q11: PRJ00522 | S11: PRJ00522 | U11: PRJ00522 | W11: PRJ00522
A12: PRJ00542 | B12: 4900000 | C12: PRJ00542 | D12: 941176 | E12: PRJ00542 | F12: 10120482 | G12: PRJ00542 | H12: 13714286 | I12: PRJ00542 | J12: 5126761 | K12: PRJ00542 | L12: 5768106 | M12: PRJ00542 | N12: 8620690 | O12: PRJ00542 | Q12: PRJ00542 | S12: PRJ00542 | U12: PRJ00542 | W12: PRJ00542
A13: PRJ00902 | B13: 2800000 | C13: PRJ00902 | D13: 1882353 | E13: PRJ00902 | F13: 9108434 | G13: PRJ00902 | H13: 13714286 | I13: PRJ00902 | J13: 11535211 | K13: PRJ00902 | L13: 14061049 | M13: PRJ00902 | N13: 0 | O13: PRJ00902 | Q13: PRJ00902 | S13: PRJ00902 | U13: PRJ00902 | W13: PRJ00902
... A41: PRJ00957 | B41: 0 | C41: PRJ00957 | D41: 0 | E41: PRJ00957 | F41: 0 | G41: PRJ00957 | H41: 0 | I41: PRJ00957 | J41: 0 | K41: PRJ00957 | L41: 0 | M41: PRJ00957 | N41: 0 | O41: PRJ00957 | Q41: PRJ00957 | S41: PRJ00957 | U41: PRJ00957 | W41: PRJ00957
A42: PRJ00038 | B42: ='Generate Dummy Closed WON (Reve'!D72 -> 8011079.2 | C42: PRJ00038 | D42: ='Generate Dummy Closed WON (Reve'!E72 -> 8011079.2 | E42: PRJ00038 | F42: ='Generate Dummy Closed WON (Reve'!F72 -> 16022158 | G42: PRJ00038 | H42: ='Generate Dummy Closed WON (Reve'!G72 -> 13084763 | I42: PRJ00038 | J42: ='Generate Dummy Closed WON (Reve'!H72 -> 11749583 | K42: PRJ00038 | L42: ='Generate Dummy Closed WON (Reve'!I72 -> 30041547 | M42: PRJ00038 | N42: ='Generate Dummy Closed WON (Reve'!J72 -> 27638223 | O42: PRJ00038 | Q42: PRJ00038 | S42: PRJ00038 | U42: PRJ00038 | W42: PRJ00038
A43: PRJ00078 | B43: ='Generate Dummy Closed WON (Reve'!D73 -> 3433319.6 | C43: PRJ00078 | D43: ='Generate Dummy Closed WON (Reve'!E73 -> 3433319.6 | E43: PRJ00078 | F43: ='Generate Dummy Closed WON (Reve'!F73 -> 6866639.3 | G43: PRJ00078 | H43: ='Generate Dummy Closed WON (Reve'!G73 -> 5607755.4 | I43: PRJ00078 | J43: ='Generate Dummy Closed WON (Reve'!H73 -> 5035535.5 | K43: PRJ00078 | L43: ='Generate Dummy Closed WON (Reve'!I73 -> 12874949 | M43: PRJ00078 | N43: ='Generate Dummy Closed WON (Reve'!J73 -> 11844953 | O43: PRJ00078 | Q43: PRJ00078 | S43: PRJ00078 | U43: PRJ00078 | W43: PRJ00078
A44: PRJ00198 | B44: ='Generate Dummy Closed WON (Reve'!D74 -> 6866639.3 | C44: PRJ00198 | D44: ='Generate Dummy Closed WON (Reve'!E74 -> 6866639.3 | E44: PRJ00198 | F44: ='Generate Dummy Closed WON (Reve'!F74 -> 13733279 | G44: PRJ00198 | H44: ='Generate Dummy Closed WON (Reve'!G74 -> 11215511 | I44: PRJ00198 | J44: ='Generate Dummy Closed WON (Reve'!H74 -> 10071071 | K44: PRJ00198 | L44: ='Generate Dummy Closed WON (Reve'!I74 -> 25749897 | M44: PRJ00198 | N44: ='Generate Dummy Closed WON (Reve'!J74 -> 23689906 | O44: PRJ00198 | Q44: PRJ00198 | S44: PRJ00198 | U44: PRJ00198 | W44: PRJ00198
A45: PRJ00269 | B45: ='Generate Dummy Closed WON (Reve'!D75 -> 8011079.2 | C45: PRJ00269 | D45: ='Generate Dummy Closed WON (Reve'!E75 -> 8011079.2 | E45: PRJ00269 | F45: ='Generate Dummy Closed WON (Reve'!F75 -> 16022158 | G45: PRJ00269 | H45: ='Generate Dummy Closed WON (Reve'!G75 -> 13084763 | I45: PRJ00269 | J45: ='Generate Dummy Closed WON (Reve'!H75 -> 11749583 | K45: PRJ00269 | L45: ='Generate Dummy Closed WON (Reve'!I75 -> 30041547 | M45: PRJ00269 | N45: ='Generate Dummy Closed WON (Reve'!J75 -> 27638223 | O45: PRJ00269 | Q45: PRJ00269 | S45: PRJ00269 | U45: PRJ00269 | W45: PRJ00269
A46: PRJ00378 | B46: ='Generate Dummy Closed WON (Reve'!D76 -> 3433319.6 | C46: PRJ00378 | D46: ='Generate Dummy Closed WON (Reve'!E76 -> 3433319.6 | E46: PRJ00378 | F46: ='Generate Dummy Closed WON (Reve'!F76 -> 6866639.3 | G46: PRJ00378 | H46: ='Generate Dummy Closed WON (Reve'!G76 -> 5607755.4 | I46: PRJ00378 | J46: ='Generate Dummy Closed WON (Reve'!H76 -> 5035535.5 | K46: PRJ00378 | L46: ='Generate Dummy Closed WON (Reve'!I76 -> 12874949 | M46: PRJ00378 | N46: ='Generate Dummy Closed WON (Reve'!J76 -> 11844953 | O46: PRJ00378 | Q46: PRJ00378 | S46: PRJ00378 | U46: PRJ00378 | W46: PRJ00378
A47: PRJ00509 | B47: ='Generate Dummy Closed WON (Reve'!D77 -> 4577759.5 | C47: PRJ00509 | D47: ='Generate Dummy Closed WON (Reve'!E77 -> 4577759.5 | E47: PRJ00509 | F47: ='Generate Dummy Closed WON (Reve'!F77 -> 9155519.1 | G47: PRJ00509 | H47: ='Generate Dummy Closed WON (Reve'!G77 -> 7477007.2 | I47: PRJ00509 | J47: ='Generate Dummy Closed WON (Reve'!H77 -> 6714047.3 | K47: PRJ00509 | L47: ='Generate Dummy Closed WON (Reve'!I77 -> 17166598 | M47: PRJ00509 | N47: ='Generate Dummy Closed WON (Reve'!J77 -> 15793270 | O47: PRJ00509 | Q47: PRJ00509 | S47: PRJ00509 | U47: PRJ00509 | W47: PRJ00509
A48: PRJ00569 | B48: ='Generate Dummy Closed WON (Reve'!D78 -> 9155519.1 | C48: PRJ00569 | D48: ='Generate Dummy Closed WON (Reve'!E78 -> 9155519.1 | E48: PRJ00569 | F48: ='Generate Dummy Closed WON (Reve'!F78 -> 18311038 | G48: PRJ00569 | H48: ='Generate Dummy Closed WON (Reve'!G78 -> 14954014 | I48: PRJ00569 | J48: ='Generate Dummy Closed WON (Reve'!H78 -> 13428095 | K48: PRJ00569 | L48: ='Generate Dummy Closed WON (Reve'!I78 -> 34333196 | M48: PRJ00569 | N48: ='Generate Dummy Closed WON (Reve'!J78 -> 31586541 | O48: PRJ00569 | Q48: PRJ00569 | S48: PRJ00569 | U48: PRJ00569 | W48: PRJ00569
A49: PRJ00669 | B49: ='Generate Dummy Closed WON (Reve'!D79 -> 9155519.1 | C49: PRJ00669 | D49: ='Generate Dummy Closed WON (Reve'!E79 -> 9155519.1 | E49: PRJ00669 | F49: ='Generate Dummy Closed WON (Reve'!F79 -> 18311038 | G49: PRJ00669 | H49: ='Generate Dummy Closed WON (Reve'!G79 -> 14954014 | I49: PRJ00669 | J49: ='Generate Dummy Closed WON (Reve'!H79 -> 13428095 | K49: PRJ00669 | L49: ='Generate Dummy Closed WON (Reve'!I79 -> 34333196 | M49: PRJ00669 | N49: ='Generate Dummy Closed WON (Reve'!J79 -> 31586541 | O49: PRJ00669 | Q49: PRJ00669 | S49: PRJ00669 | U49: PRJ00669 | W49: PRJ00669
A50: PRJ00829 | B50: ='Generate Dummy Closed WON (Reve'!D80 -> 6866639.3 | C50: PRJ00829 | D50: ='Generate Dummy Closed WON (Reve'!E80 -> 6866639.3 | E50: PRJ00829 | F50: ='Generate Dummy Closed WON (Reve'!F80 -> 13733279 | G50: PRJ00829 | H50: ='Generate Dummy Closed WON (Reve'!G80 -> 11215511 | I50: PRJ00829 | J50: ='Generate Dummy Closed WON (Reve'!H80 -> 10071071 | K50: PRJ00829 | L50: ='Generate Dummy Closed WON (Reve'!I80 -> 25749897 | M50: PRJ00829 | N50: ='Generate Dummy Closed WON (Reve'!J80 -> 23689906 | O50: PRJ00829 | Q50: PRJ00829 | S50: PRJ00829 | U50: PRJ00829 | W50: PRJ00829
A51: PRJ00878 | B51: ='Generate Dummy Closed WON (Reve'!D81 -> 9155519.1 | C51: PRJ00878 | D51: ='Generate Dummy Closed WON (Reve'!E81 -> 9155519.1 | E51: PRJ00878 | F51: ='Generate Dummy Closed WON (Reve'!F81 -> 18311038 | G51: PRJ00878 | H51: ='Generate Dummy Closed WON (Reve'!G81 -> 14954014 | I51: PRJ00878 | J51: ='Generate Dummy Closed WON (Reve'!H81 -> 13428095 | K51: PRJ00878 | L51: ='Generate Dummy Closed WON (Reve'!I81 -> 34333196 | M51: PRJ00878 | N51: ='Generate Dummy Closed WON (Reve'!J81 -> 31586541 | O51: PRJ00878 | Q51: PRJ00878 | S51: PRJ00878 | U51: PRJ00878 | W51: PRJ00878
A52: PRJ00889 | B52: ='Generate Dummy Closed WON (Reve'!D82 -> 11444399 | C52: PRJ00889 | D52: ='Generate Dummy Closed WON (Reve'!E82 -> 11444399 | E52: PRJ00889 | F52: ='Generate Dummy Closed WON (Reve'!F82 -> 22888798 | G52: PRJ00889 | H52: ='Generate Dummy Closed WON (Reve'!G82 -> 18692518 | I52: PRJ00889 | J52: ='Generate Dummy Closed WON (Reve'!H82 -> 16785118 | K52: PRJ00889 | L52: ='Generate Dummy Closed WON (Reve'!I82 -> 42916496 | M52: PRJ00889 | N52: ='Generate Dummy Closed WON (Reve'!J82 -> 39483176 | O52: PRJ00889 | Q52: PRJ00889 | S52: PRJ00889 | U52: PRJ00889 | W52: PRJ00889
A53: PRJ00949 | B53: ='Generate Dummy Closed WON (Reve'!D83 -> 3433319.6 | C53: PRJ00949 | D53: ='Generate Dummy Closed WON (Reve'!E83 -> 3433319.6 | E53: PRJ00949 | F53: ='Generate Dummy Closed WON (Reve'!F83 -> 6866639.3 | G53: PRJ00949 | H53: ='Generate Dummy Closed WON (Reve'!G83 -> 5607755.4 | I53: PRJ00949 | J53: ='Generate Dummy Closed WON (Reve'!H83 -> 5035535.5 | K53: PRJ00949 | L53: ='Generate Dummy Closed WON (Reve'!I83 -> 12874949 | M53: PRJ00949 | N53: ='Generate Dummy Closed WON (Reve'!J83 -> 11844953 | O53: PRJ00949 | Q53: PRJ00949 | S53: PRJ00949 | U53: PRJ00949 | W53: PRJ00949
A54: PRJ00075 | B54: ='Generate Dummy Closed WON (Reve'!O72 -> 5569607.4 | C54: =A54 -> PRJ00075 | D54: ='Generate Dummy Closed WON (Reve'!P72 -> 5569607.4 | E54: =A54 -> PRJ00075 | F54: ='Generate Dummy Closed WON (Reve'!Q72 -> 11139215 | G54: =A54 -> PRJ00075 | H54: ='Generate Dummy Closed WON (Reve'!R72 -> 9097025.5 | I54: =G54 -> PRJ00075 | J54: ='Generate Dummy Closed WON (Reve'!S72 -> 8168757.6 | K54: =I54 -> PRJ00075 | L54: ='Generate Dummy Closed WON (Reve'!T72 -> 20886028 | M54: =K54 -> PRJ00075 | N54: ='Generate Dummy Closed WON (Reve'!U72 -> 19215146 | O54: =M54 -> PRJ00075 | Q54: =O54 -> PRJ00075 | S54: =Q54 -> PRJ00075 | U54: =S54 -> PRJ00075 | W54: =U54 -> PRJ00075
A55: PRJ00105 | B55: ='Generate Dummy Closed WON (Reve'!O73 -> 3341764.5 | C55: =A55 -> PRJ00105 | D55: ='Generate Dummy Closed WON (Reve'!P73 -> 3341764.5 | E55: =A55 -> PRJ00105 | F55: ='Generate Dummy Closed WON (Reve'!Q73 -> 6683528.9 | G55: =A55 -> PRJ00105 | H55: ='Generate Dummy Closed WON (Reve'!R73 -> 5458215.3 | I55: =G55 -> PRJ00105 | J55: ='Generate Dummy Closed WON (Reve'!S73 -> 4901254.5 | K55: =I55 -> PRJ00105 | L55: ='Generate Dummy Closed WON (Reve'!T73 -> 12531617 | M55: =K55 -> PRJ00105 | N55: ='Generate Dummy Closed WON (Reve'!U73 -> 11529087 | O55: =M55 -> PRJ00105 | Q55: =O55 -> PRJ00105 | S55: =Q55 -> PRJ00105 | U55: =S55 -> PRJ00105 | W55: =U55 -> PRJ00105
A56: PRJ00125 | B56: ='Generate Dummy Closed WON (Reve'!O74 -> 6683528.9 | C56: =A56 -> PRJ00125 | D56: ='Generate Dummy Closed WON (Reve'!P74 -> 6683528.9 | E56: =A56 -> PRJ00125 | F56: ='Generate Dummy Closed WON (Reve'!Q74 -> 13367058 | G56: =A56 -> PRJ00125 | H56: ='Generate Dummy Closed WON (Reve'!R74 -> 10916431 | I56: =G56 -> PRJ00125 | J56: ='Generate Dummy Closed WON (Reve'!S74 -> 9802509.1 | K56: =I56 -> PRJ00125 | L56: ='Generate Dummy Closed WON (Reve'!T74 -> 25063233 | M56: =K56 -> PRJ00125 | N56: ='Generate Dummy Closed WON (Reve'!U74 -> 23058175 | O56: =M56 -> PRJ00125 | Q56: =O56 -> PRJ00125 | S56: =Q56 -> PRJ00125 | U56: =S56 -> PRJ00125 | W56: =U56 -> PRJ00125
A57: PRJ00145 | B57: ='Generate Dummy Closed WON (Reve'!O75 -> 1113921.5 | C57: =A57 -> PRJ00145 | D57: ='Generate Dummy Closed WON (Reve'!P75 -> 1113921.5 | E57: =A57 -> PRJ00145 | F57: ='Generate Dummy Closed WON (Reve'!Q75 -> 2227843 | G57: =A57 -> PRJ00145 | H57: ='Generate Dummy Closed WON (Reve'!R75 -> 1819405.1 | I57: =G57 -> PRJ00145 | J57: ='Generate Dummy Closed WON (Reve'!S75 -> 1633751.5 | K57: =I57 -> PRJ00145 | L57: ='Generate Dummy Closed WON (Reve'!T75 -> 4177205.6 | M57: =K57 -> PRJ00145 | N57: ='Generate Dummy Closed WON (Reve'!U75 -> 3843029.1 | O57: =M57 -> PRJ00145 | Q57: =O57 -> PRJ00145 | S57: =Q57 -> PRJ00145 | U57: =S57 -> PRJ00145 | W57: =U57 -> PRJ00145
A58: PRJ00153 | B58: ='Generate Dummy Closed WON (Reve'!O76 -> 4455685.9 | C58: =A58 -> PRJ00153 | D58: ='Generate Dummy Closed WON (Reve'!P76 -> 4455685.9 | E58: =A58 -> PRJ00153 | F58: ='Generate Dummy Closed WON (Reve'!Q76 -> 8911371.9 | G58: =A58 -> PRJ00153 | H58: ='Generate Dummy Closed WON (Reve'!R76 -> 7277620.4 | I58: =G58 -> PRJ00153 | J58: ='Generate Dummy Closed WON (Reve'!S76 -> 6535006 | K58: =I58 -> PRJ00153 | L58: ='Generate Dummy Closed WON (Reve'!T76 -> 0 | M58: =K58 -> PRJ00153 | N58: ='Generate Dummy Closed WON (Reve'!U76 -> 15372116 | O58: =M58 -> PRJ00153 | Q58: =O58 -> PRJ00153 | S58: =Q58 -> PRJ00153 | U58: =S58 -> PRJ00153 | W58: =U58 -> PRJ00153
A59: PRJ00193 | B59: ='Generate Dummy Closed WON (Reve'!O77 -> 8911371.9 | C59: =A59 -> PRJ00193 | D59: ='Generate Dummy Closed WON (Reve'!P77 -> 8911371.9 | E59: =A59 -> PRJ00193 | F59: ='Generate Dummy Closed WON (Reve'!Q77 -> 17822744 | G59: =A59 -> PRJ00193 | H59: ='Generate Dummy Closed WON (Reve'!R77 -> 14555241 | I59: =G59 -> PRJ00193 | J59: ='Generate Dummy Closed WON (Reve'!S77 -> 13070012 | K59: =I59 -> PRJ00193 | L59: ='Generate Dummy Closed WON (Reve'!T77 -> 33417645 | M59: =K59 -> PRJ00193 | N59: ='Generate Dummy Closed WON (Reve'!U77 -> 30744233 | O59: =M59 -> PRJ00193 | Q59: =O59 -> PRJ00193 | S59: =Q59 -> PRJ00193 | U59: =S59 -> PRJ00193 | W59: =U59 -> PRJ00193
A60: PRJ00253 | B60: ='Generate Dummy Closed WON (Reve'!O78 -> 11139215 | C60: =A60 -> PRJ00253 | D60: ='Generate Dummy Closed WON (Reve'!P78 -> 11139215 | E60: =A60 -> PRJ00253 | F60: ='Generate Dummy Closed WON (Reve'!Q78 -> 22278430 | G60: =A60 -> PRJ00253 | H60: ='Generate Dummy Closed WON (Reve'!R78 -> 18194051 | I60: =G60 -> PRJ00253 | J60: ='Generate Dummy Closed WON (Reve'!S78 -> 16337515 | K60: =I60 -> PRJ00253 | L60: ='Generate Dummy Closed WON (Reve'!T78 -> 41772056 | M60: =K60 -> PRJ00253 | N60: ='Generate Dummy Closed WON (Reve'!U78 -> 38430291 | O60: =M60 -> PRJ00253 | Q60: =O60 -> PRJ00253 | S60: =Q60 -> PRJ00253 | U60: =S60 -> PRJ00253 | W60: =U60 -> PRJ00253
A61: PRJ00305 | B61: ='Generate Dummy Closed WON (Reve'!O79 -> 5569607.4 | C61: =A61 -> PRJ00305 | D61: ='Generate Dummy Closed WON (Reve'!P79 -> 5569607.4 | E61: =A61 -> PRJ00305 | F61: ='Generate Dummy Closed WON (Reve'!Q79 -> 11139215 | G61: =A61 -> PRJ00305 | H61: ='Generate Dummy Closed WON (Reve'!R79 -> 9097025.5 | I61: =G61 -> PRJ00305 | J61: ='Generate Dummy Closed WON (Reve'!S79 -> 8168757.6 | K61: =I61 -> PRJ00305 | L61: ='Generate Dummy Closed WON (Reve'!T79 -> 20886028 | M61: =K61 -> PRJ00305 | N61: ='Generate Dummy Closed WON (Reve'!U79 -> 19215146 | O61: =M61 -> PRJ00305 | Q61: =O61 -> PRJ00305 | S61: =Q61 -> PRJ00305 | U61: =S61 -> PRJ00305 | W61: =U61 -> PRJ00305
A62: PRJ00445 | B62: ='Generate Dummy Closed WON (Reve'!O80 -> 2227843 | C62: =A62 -> PRJ00445 | D62: ='Generate Dummy Closed WON (Reve'!P80 -> 2227843 | E62: =A62 -> PRJ00445 | F62: ='Generate Dummy Closed WON (Reve'!Q80 -> 0 | G62: =A62 -> PRJ00445 | H62: ='Generate Dummy Closed WON (Reve'!R80 -> 3638810.2 | I62: =G62 -> PRJ00445 | J62: ='Generate Dummy Closed WON (Reve'!S80 -> 3267503 | K62: =I62 -> PRJ00445 | L62: ='Generate Dummy Closed WON (Reve'!T80 -> 8354411.1 | M62: =K62 -> PRJ00445 | N62: ='Generate Dummy Closed WON (Reve'!U80 -> 7686058.2 | O62: =M62 -> PRJ00445 | Q62: =O62 -> PRJ00445 | S62: =Q62 -> PRJ00445 | U62: =S62 -> PRJ00445 | W62: =U62 -> PRJ00445
A63: PRJ00585 | B63: ='Generate Dummy Closed WON (Reve'!O81 -> 5569607.4 | C63: =A63 -> PRJ00585 | D63: ='Generate Dummy Closed WON (Reve'!P81 -> 5569607.4 | E63: =A63 -> PRJ00585 | F63: ='Generate Dummy Closed WON (Reve'!Q81 -> 11139215 | G63: =A63 -> PRJ00585 | H63: ='Generate Dummy Closed WON (Reve'!R81 -> 9097025.5 | I63: =G63 -> PRJ00585 | J63: ='Generate Dummy Closed WON (Reve'!S81 -> 8168757.6 | K63: =I63 -> PRJ00585 | L63: ='Generate Dummy Closed WON (Reve'!T81 -> 20886028 | M63: =K63 -> PRJ00585 | N63: ='Generate Dummy Closed WON (Reve'!U81 -> 19215146 | O63: =M63 -> PRJ00585 | Q63: =O63 -> PRJ00585 | S63: =Q63 -> PRJ00585 | U63: =S63 -> PRJ00585 | W63: =U63 -> PRJ00585
A64: PRJ00605 | B64: ='Generate Dummy Closed WON (Reve'!O82 -> 0 | C64: =A64 -> PRJ00605 | D64: ='Generate Dummy Closed WON (Reve'!P82 -> 11139215 | E64: =A64 -> PRJ00605 | F64: ='Generate Dummy Closed WON (Reve'!Q82 -> 22278430 | G64: =A64 -> PRJ00605 | H64: ='Generate Dummy Closed WON (Reve'!R82 -> 18194051 | I64: =G64 -> PRJ00605 | J64: ='Generate Dummy Closed WON (Reve'!S82 -> 16337515 | K64: =I64 -> PRJ00605 | L64: ='Generate Dummy Closed WON (Reve'!T82 -> 41772056 | M64: =K64 -> PRJ00605 | N64: ='Generate Dummy Closed WON (Reve'!U82 -> 38430291 | O64: =M64 -> PRJ00605 | Q64: =O64 -> PRJ00605 | S64: =Q64 -> PRJ00605 | U64: =S64 -> PRJ00605 | W64: =U64 -> PRJ00605
A65: PRJ00673 | B65: ='Generate Dummy Closed WON (Reve'!O83 -> 11139215 | C65: =A65 -> PRJ00673 | D65: ='Generate Dummy Closed WON (Reve'!P83 -> 0 | E65: =A65 -> PRJ00673 | F65: ='Generate Dummy Closed WON (Reve'!Q83 -> 4455685.9 | G65: =A65 -> PRJ00673 | H65: ='Generate Dummy Closed WON (Reve'!R83 -> 0 | I65: =G65 -> PRJ00673 | J65: ='Generate Dummy Closed WON (Reve'!S83 -> 0 | K65: =I65 -> PRJ00673 | L65: ='Generate Dummy Closed WON (Reve'!T83 -> 16708822 | M65: =K65 -> PRJ00673 | N65: ='Generate Dummy Closed WON (Reve'!U83 -> 0 | O65: =M65 -> PRJ00673 | Q65: =O65 -> PRJ00673 | S65: =Q65 -> PRJ00673 | U65: =S65 -> PRJ00673 | W65: =U65 -> PRJ00673
... A70: PRJ01000 | B70: ='Generate Dummy Closed WON (Reve'!O88 -> 2227843 | C70: =A70 -> PRJ01000 | D70: ='Generate Dummy Closed WON (Reve'!P88 -> 2227843 | E70: =A70 -> PRJ01000 | F70: ='Generate Dummy Closed WON (Reve'!Q88 -> 4455685.9 | G70: =A70 -> PRJ01000 | H70: ='Generate Dummy Closed WON (Reve'!R88 -> 3638810.2 | I70: =G70 -> PRJ01000 | J70: ='Generate Dummy Closed WON (Reve'!S88 -> 3267503 | K70: =I70 -> PRJ01000 | L70: ='Generate Dummy Closed WON (Reve'!T88 -> 8354411.1 | M70: =K70 -> PRJ01000 | N70: ='Generate Dummy Closed WON (Reve'!U88 -> 7686058.2 | O70: =M70 -> PRJ01000 | Q70: =O70 -> PRJ01000 | S70: =Q70 -> PRJ01000 | U70: =S70 -> PRJ01000 | W70: =U70 -> PRJ01000
A71: ='Generate Dummy Closed WON (Reve'!A94 -> PRJ00023 | B71: ='Generate Dummy Closed WON (Reve'!D94 -> 1326097 | C71: =A71 -> PRJ00023 | D71: ='Generate Dummy Closed WON (Reve'!E94 -> 1326097 | E71: =A71 -> PRJ00023 | F71: ='Generate Dummy Closed WON (Reve'!F94 -> 2652194 | G71: =E71 -> PRJ00023 | H71: ='Generate Dummy Closed WON (Reve'!G94 -> 2165958.4 | I71: =G71 -> PRJ00023 | J71: ='Generate Dummy Closed WON (Reve'!H94 -> 1944942.3 | K71: =I71 -> PRJ00023 | L71: ='Generate Dummy Closed WON (Reve'!I94 -> 4972863.8 | M71: =K71 -> PRJ00023 | N71: ='Generate Dummy Closed WON (Reve'!J94 -> 4575034.7 | O71: =M71 -> PRJ00023
...

Sheet Account Data
A1: p_id | B1: ac_id | C1: ac | D1: stage | E1: product_category | F1: product_name | G1: am_id | H1: am | I1: area_id | J1: plan_jan | K1: plan_feb | L1: plan_mar | M1: plan_apr | N1: plan_may | O1: plan_jun | P1: plan_jul | Q1: plan_aug | R1: plan_sep | S1: plan_oct | T1: plan_nov | U1: plan_dec | V1: revenue_jan | W1: revenue_feb | X1: revenue_mar | Y1: revenue_apr | Z1: revenue_may | AA1: revenue_jun | AB1: revenue_jul | AC1: revenue_aug | AD1: revenue_sep | AE1: revenue_oct | AF1: revenue_nov | AG1: revenue_dec
A2: PRJ00001 | B2: CL00001 | C2: =CHOOSE(MOD(ROW()-2, 20)+1, "PT. Maju Jaya", "CV. Sumber Makmur", "PT. Teknologi Nusantara", "PT. Bakti Indonesia", "CV. Amanah Sejahtera", "PT. Digital Solusi Pratama", "PT. Global Niaga Abadi", "PT. Indo Makmur Sentosa", "PT. Citra Mandiri Utama", "PT. Sinar Dunia Baru", "CV. Karya Utama Mandiri", "PT. Pratama Jaya Sentosa", "PT. Abadi Selamanya Jaya", "PT. Mandiri Sejahtera Bersama", "PT. Sejahtera Alam Indonesia", "PT. Indah Kargo Logistik", "PT. Berkah Alam Semesta", "PT. Cahaya Baru Indonesia", "PT. Mentari Pagi Sejahtera", "PT. Bintang Kejora Nusantara") -> PT. Maju Jaya | D2: Proposal | E2: Cloud Services | F2: Nexa Cloud Basic | G2: AM003 | H2: {=XLOOKUP(G:G,'Account Manager Data'!A:A,'Account Manager Data'!B:B,0)} -> Ahmad Fauzi | I2: {=XLOOKUP($G:$G,'Account Manager Data'!$A:$A,'Account Manager Data'!C:C)} -> Sumatera | J2: 2966160 | K2: 7797707 | L2: 751234 | M2: 6323056 | N2: 0 | O2: 7185676 | P2: 11266926 | Q2: 2659407 | R2: 9503335 | S2: 3919266 | T2: 14726687 | U2: 17308622 | V2: {=XLOOKUP(A:A,'Raw Revenue'!A:A,'Raw Revenue'!B:B,0)} -> 0 | W2: {=XLOOKUP(A:A,'Raw Revenue'!C:C,'Raw Revenue'!D:D,0)} -> 0 | X2: {=XLOOKUP(A:A,'Raw Revenue'!E:E,'Raw Revenue'!F:F,0)} -> 0 | Y2: {=XLOOKUP(A:A,'Raw Revenue'!G:G,'Raw Revenue'!H:H,0)} -> 0 | Z2: {=XLOOKUP(A:A,'Raw Revenue'!I:I,'Raw Revenue'!J:J,0)} -> 0 | AA2: {=XLOOKUP(A:A,'Raw Revenue'!K:K,'Raw Revenue'!L:L,0)} -> 0 | AB2: {=XLOOKUP(A:A,'Raw Revenue'!M:M,'Raw Revenue'!N:N,0)} -> 0 | AC2: 0 | AD2: 0 | AE2: 0 | AF2: 0 | AG2: 0
A3: PRJ00002 | B3: CL00002 | C3: =CHOOSE(MOD(ROW()-2, 20)+1, "PT. Maju Jaya", "CV. Sumber Makmur", "PT. Teknologi Nusantara", "PT. Bakti Indonesia", "CV. Amanah Sejahtera", "PT. Digital Solusi Pratama", "PT. Global Niaga Abadi", "PT. Indo Makmur Sentosa", "PT. Citra Mandiri Utama", "PT. Sinar Dunia Baru", "CV. Karya Utama Mandiri", "PT. Pratama Jaya Sentosa", "PT. Abadi Selamanya Jaya", "PT. Mandiri Sejahtera Bersama", "PT. Sejahtera Alam Indonesia", "PT. Indah Kargo Logistik", "PT. Berkah Alam Semesta", "PT. Cahaya Baru Indonesia", "PT. Mentari Pagi Sejahtera", "PT. Bintang Kejora Nusantara") -> CV. Sumber Makmur | D3: Closed Won | E3: Data Analytics | F3: Insight BI Platform | G3: AM010 | H3: {=XLOOKUP(G:G,'Account Manager Data'!A:A,'Account Manager Data'!B:B,0)} -> Ilham Saputra | I3: {=XLOOKUP($G:$G,'Account Manager Data'!$A:$A,'Account Manager Data'!C:C)} -> Jawa | J3: 2567102 | K3: 8814418 | L3: 7699551 | M3: 2258874 | N3: 4255237 | O3: 10378660 | P3: 1520933 | Q3: 9481838 | R3: 0 | S3: 9772055 | T3: 659754 | U3: 17477879 | V3: {=XLOOKUP(A:A,'Raw Revenue'!A:A,'Raw Revenue'!B:B,0)} -> 357026.12 | W3: {=XLOOKUP(A:A,'Raw Revenue'!C:C,'Raw Revenue'!D:D,0)} -> 178513.06 | X3: {=XLOOKUP(A:A,'Raw Revenue'!E:E,'Raw Revenue'!F:F,0)} -> 107107.84 | Y3: {=XLOOKUP(A:A,'Raw Revenue'!G:G,'Raw Revenue'!H:H,0)} -> 1249591.4 | Z3: {=XLOOKUP(A:A,'Raw Revenue'!I:I,'Raw Revenue'!J:J,0)} -> 285620.89 | AA3: {=XLOOKUP(A:A,'Raw Revenue'!K:K,'Raw Revenue'!L:L,0)} -> 8033.0876 | AB3: {=XLOOKUP(A:A,'Raw Revenue'!M:M,'Raw Revenue'!N:N,0)} -> 1076433.7 | AC3: 0 | AD3: 0 | AE3: 0 | AF3: 0 | AG3: 0
A4: PRJ00003 | B4: CL00003 | C4: =CHOOSE(MOD(ROW()-2, 20)+1, "PT. Maju Jaya", "CV. Sumber Makmur", "PT. Teknologi Nusantara", "PT. Bakti Indonesia", "CV. Amanah Sejahtera", "PT. Digital Solusi Pratama", "PT. Global Niaga Abadi", "PT. Indo Makmur Sentosa", "PT. Citra Mandiri Utama", "PT. Sinar Dunia Baru", "CV. Karya Utama Mandiri", "PT. Pratama Jaya Sentosa", "PT. Abadi Selamanya Jaya", "PT. Mandiri Sejahtera Bersama", "PT. Sejahtera Alam Indonesia", "PT. Indah Kargo Logistik", "PT. Berkah Alam Semesta", "PT. Cahaya Baru Indonesia", "PT. Mentari Pagi Sejahtera", "PT. Bintang Kejora Nusantara") -> PT. Teknologi Nusantara | D4: Negotiation | E4: Data Analytics | F4: Realtime Dashboard Pro | G4: AM006 | H4: {=XLOOKUP(G:G,'Account Manager Data'!A:A,'Account Manager Data'!B:B,0)} -> Hendra Gunawan | I4: {=XLOOKUP($G:$G,'Account Manager Data'!$A:$A,'Account Manager Data'!C:C)} -> Kalimantan | J4: 3246821 | K4: 7539407 | L4: 5913756 | M4: 5653365 | N4: 13522904 | O4: 10837711 | P4: 1511364 | Q4: 10962390 | R4: 9730111 | S4: 15947569 | T4: 16258577 | U4: 11898873 | V4: {=XLOOKUP(A:A,'Raw Revenue'!A:A,'Raw Revenue'!B:B,0)} -> 0 | W4: {=XLOOKUP(A:A,'Raw Revenue'!C:C,'Raw Revenue'!D:D,0)} -> 0 | X4: {=XLOOKUP(A:A,'Raw Revenue'!E:E,'Raw Revenue'!F:F,0)} -> 0 | Y4: {=XLOOKUP(A:A,'Raw Revenue'!G:G,'Raw Revenue'!H:H,0)} -> 0 | Z4: {=XLOOKUP(A:A,'Raw Revenue'!I:I,'Raw Revenue'!J:J,0)} -> 0 | AA4: {=XLOOKUP(A:A,'Raw Revenue'!K:K,'Raw Revenue'!L:L,0)} -> 0 | AB4: {=XLOOKUP(A:A,'Raw Revenue'!M:M,'Raw Revenue'!N:N,0)} -> 0 | AC4: 0 | AD4: 0 | AE4: 0 | AF4: 0 | AG4: 0
A5: PRJ00004 | B5: CL00004 | C5: =CHOOSE(MOD(ROW()-2, 20)+1, "PT. Maju Jaya", "CV. Sumber Makmur", "PT. Teknologi Nusantara", "PT. Bakti Indonesia", "CV. Amanah Sejahtera", "PT. Digital Solusi Pratama", "PT. Global Niaga Abadi", "PT. Indo Makmur Sentosa", "PT. Citra Mandiri Utama", "PT. Sinar Dunia Baru", "CV. Karya Utama Mandiri", "PT. Pratama Jaya Sentosa", "PT. Abadi Selamanya Jaya", "PT. Mandiri Sejahtera Bersama", "PT. Sejahtera Alam Indonesia", "PT. Indah Kargo Logistik", "PT. Berkah Alam Semesta", "PT. Cahaya Baru Indonesia", "PT. Mentari Pagi Sejahtera", "PT. Bintang Kejora Nusantara") -> PT. Bakti Indonesia | D5: Proposal | E5: Data Analytics | F5: Realtime Dashboard Pro | G5: AM005 | H5: {=XLOOKUP(G:G,'Account Manager Data'!A:A,'Account Manager Data'!B:B,0)} -> Fajar Ramadhan | I5: {=XLOOKUP($G:$G,'Account Manager Data'!$A:$A,'Account Manager Data'!C:C)} -> Sulawesi | J5: 7961114 | K5: 6416594 | L5: 10340700 | M5: 6438716 | N5: 8958457 | O5: 5382337 | P5: 9460617 | Q5: 1439939 | R5: 12895421 | S5: 1857318 | T5: 5494109 | U5: 0 | V5: {=XLOOKUP(A:A,'Raw Revenue'!A:A,'Raw Revenue'!B:B,0)} -> 0 | W5: {=XLOOKUP(A:A,'Raw Revenue'!C:C,'Raw Revenue'!D:D,0)} -> 0 | X5: {=XLOOKUP(A:A,'Raw Revenue'!E:E,'Raw Revenue'!F:F,0)} -> 0 | Y5: {=XLOOKUP(A:A,'Raw Revenue'!G:G,'Raw Revenue'!H:H,0)} -> 0 | Z5: {=XLOOKUP(A:A,'Raw Revenue'!I:I,'Raw Revenue'!J:J,0)} -> 0 | AA5: {=XLOOKUP(A:A,'Raw Revenue'!K:K,'Raw Revenue'!L:L,0)} -> 0 | AB5: {=XLOOKUP(A:A,'Raw Revenue'!M:M,'Raw Revenue'!N:N,0)} -> 0 | AC5: 0 | AD5: 0 | AE5: 0 | AF5: 0 | AG5: 0
A6: PRJ00005 | B6: CL00005 | C6: =CHOOSE(MOD(ROW()-2, 20)+1, "PT. Maju Jaya", "CV. Sumber Makmur", "PT. Teknologi Nusantara", "PT. Bakti Indonesia", "CV. Amanah Sejahtera", "PT. Digital Solusi Pratama", "PT. Global Niaga Abadi", "PT. Indo Makmur Sentosa", "PT. Citra Mandiri Utama", "PT. Sinar Dunia Baru", "CV. Karya Utama Mandiri", "PT. Pratama Jaya Sentosa", "PT. Abadi Selamanya Jaya", "PT. Mandiri Sejahtera Bersama", "PT. Sejahtera Alam Indonesia", "PT. Indah Kargo Logistik", "PT. Berkah Alam Semesta", "PT. Cahaya Baru Indonesia", "PT. Mentari Pagi Sejahtera", "PT. Bintang Kejora Nusantara") -> CV. Amanah Sejahtera | D6: Prospect | E6: Cyber Security | F6: SOC Monitoring | G6: AM010 | H6: {=XLOOKUP(G:G,'Account Manager Data'!A:A,'Account Manager Data'!B:B,0)} -> Ilham Saputra | I6: {=XLOOKUP($G:$G,'Account Manager Data'!$A:$A,'Account Manager Data'!C:C)} -> Jawa | J6: 694281 | K6: 4642267 | L6: 4271204 | M6: 8871702 | N6: 3710476 | O6: 2790727 | P6: 4940446 | Q6: 7802209 | R6: 10901441 | S6: 14123540 | T6: 11321133 | U6: 9029935 | V6: {=XLOOKUP(A:A,'Raw Revenue'!A:A,'Raw Revenue'!B:B,0)} -> 0 | W6: {=XLOOKUP(A:A,'Raw Revenue'!C:C,'Raw Revenue'!D:D,0)} -> 0 | X6: {=XLOOKUP(A:A,'Raw Revenue'!E:E,'Raw Revenue'!F:F,0)} -> 0 | Y6: {=XLOOKUP(A:A,'Raw Revenue'!G:G,'Raw Revenue'!H:H,0)} -> 0 | Z6: {=XLOOKUP(A:A,'Raw Revenue'!I:I,'Raw Revenue'!J:J,0)} -> 0 | AA6: {=XLOOKUP(A:A,'Raw Revenue'!K:K,'Raw Revenue'!L:L,0)} -> 0 | AB6: {=XLOOKUP(A:A,'Raw Revenue'!M:M,'Raw Revenue'!N:N,0)} -> 0 | AC6: 0 | AD6: 0 | AE6: 0 | AF6: 0 | AG6: 0
A7: PRJ00006 | B7: CL00006 | C7: =CHOOSE(MOD(ROW()-2, 20)+1, "PT. Maju Jaya", "CV. Sumber Makmur", "PT. Teknologi Nusantara", "PT. Bakti Indonesia", "CV. Amanah Sejahtera", "PT. Digital Solusi Pratama", "PT. Global Niaga Abadi", "PT. Indo Makmur Sentosa", "PT. Citra Mandiri Utama", "PT. Sinar Dunia Baru", "CV. Karya Utama Mandiri", "PT. Pratama Jaya Sentosa", "PT. Abadi Selamanya Jaya", "PT. Mandiri Sejahtera Bersama", "PT. Sejahtera Alam Indonesia", "PT. Indah Kargo Logistik", "PT. Berkah Alam Semesta", "PT. Cahaya Baru Indonesia", "PT. Mentari Pagi Sejahtera", "PT. Bintang Kejora Nusantara") -> PT. Digital Solusi Pratama | D7: Closed Lost | E7: Collaboration Tools | F7: TeamSync Workspace | G7: AM001 | H7: {=XLOOKUP(G:G,'Account Manager Data'!A:A,'Account Manager Data'!B:B,0)} -> Rizky Maulana | I7: {=XLOOKUP($G:$G,'Account Manager Data'!$A:$A,'Account Manager Data'!C:C)} -> Jawa | J7: 1538794 | K7: 8884412 | L7: 8615893 | M7: 1055216 | N7: 2976622 | O7: 14923256 | P7: 3676715 | Q7: 9093131 | R7: 1002210 | S7: 1169432 | T7: 0 | U7: 14632060 | V7: {=XLOOKUP(A:A,'Raw Revenue'!A:A,'Raw Revenue'!B:B,0)} -> 0 | W7: {=XLOOKUP(A:A,'Raw Revenue'!C:C,'Raw Revenue'!D:D,0)} -> 0 | X7: {=XLOOKUP(A:A,'Raw Revenue'!E:E,'Raw Revenue'!F:F,0)} -> 0 | Y7: {=XLOOKUP(A:A,'Raw Revenue'!G:G,'Raw Revenue'!H:H,0)} -> 0 | Z7: {=XLOOKUP(A:A,'Raw Revenue'!I:I,'Raw Revenue'!J:J,0)} -> 0 | AA7: {=XLOOKUP(A:A,'Raw Revenue'!K:K,'Raw Revenue'!L:L,0)} -> 0 | AB7: {=XLOOKUP(A:A,'Raw Revenue'!M:M,'Raw Revenue'!N:N,0)} -> 0 | AC7: 0 | AD7: 0 | AE7: 0 | AF7: 0 | AG7: 0
A8: PRJ00007 | B8: CL00007 | C8: =CHOOSE(MOD(ROW()-2, 20)+1, "PT. Maju Jaya", "CV. Sumber Makmur", "PT. Teknologi Nusantara", "PT. Bakti Indonesia", "CV. Amanah Sejahtera", "PT. Digital Solusi Pratama", "PT. Global Niaga Abadi", "PT. Indo Makmur Sentosa", "PT. Citra Mandiri Utama", "PT. Sinar Dunia Baru", "CV. Karya Utama Mandiri", "PT. Pratama Jaya Sentosa", "PT. Abadi Selamanya Jaya", "PT. Mandiri Sejahtera Bersama", "PT. Sejahtera Alam Indonesia", "PT. Indah Kargo Logistik", "PT. Berkah Alam Semesta", "PT. Cahaya Baru Indonesia", "PT. Mentari Pagi Sejahtera", "PT. Bintang Kejora Nusantara") -> PT. Global Niaga Abadi | D8: Closed Won | E8: Data Analytics | F8: Realtime Dashboard Pro | G8: AM008 | H8: {=XLOOKUP(G:G,'Account Manager Data'!A:A,'Account Manager Data'!B:B,0)} -> Budi Santoso | I8: {=XLOOKUP($G:$G,'Account Manager Data'!$A:$A,'Account Manager Data'!C:C)} -> Papua | J8: 2718187 | K8: 4141754 | L8: 8835324 | M8: 379338 | N8: 11051261 | O8: 9907821 | P8: 15305877 | Q8: 11286631 | R8: 14544387 | S8: 1654939 | T8: 1292246 | U8: 17615147 | V8: {=XLOOKUP(A:A,'Raw Revenue'!A:A,'Raw Revenue'!B:B,0)} -> 1319117.5 | W8: {=XLOOKUP(A:A,'Raw Revenue'!C:C,'Raw Revenue'!D:D,0)} -> 659558.77 | X8: {=XLOOKUP(A:A,'Raw Revenue'!E:E,'Raw Revenue'!F:F,0)} -> 395735.26 | Y8: {=XLOOKUP(A:A,'Raw Revenue'!G:G,'Raw Revenue'!H:H,0)} -> 4616911.4 | Z8: {=XLOOKUP(A:A,'Raw Revenue'!I:I,'Raw Revenue'!J:J,0)} -> 1055294 | AA8: {=XLOOKUP(A:A,'Raw Revenue'!K:K,'Raw Revenue'!L:L,0)} -> 29680.145 | AB8: {=XLOOKUP(A:A,'Raw Revenue'!M:M,'Raw Revenue'!N:N,0)} -> 3977139.4 | AC8: 0 | AD8: 0 | AE8: 0 | AF8: 0 | AG8: 0
A9: PRJ00008 | B9: CL00008 | C9: =CHOOSE(MOD(ROW()-2, 20)+1, "PT. Maju Jaya", "CV. Sumber Makmur", "PT. Teknologi Nusantara", "PT. Bakti Indonesia", "CV. Amanah Sejahtera", "PT. Digital Solusi Pratama", "PT. Global Niaga Abadi", "PT. Indo Makmur Sentosa", "PT. Citra Mandiri Utama", "PT. Sinar Dunia Baru", "CV. Karya Utama Mandiri", "PT. Pratama Jaya Sentosa", "PT. Abadi Selamanya Jaya", "PT. Mandiri Sejahtera Bersama", "PT. Sejahtera Alam Indonesia", "PT. Indah Kargo Logistik", "PT. Berkah Alam Semesta", "PT. Cahaya Baru Indonesia", "PT. Mentari Pagi Sejahtera", "PT. Bintang Kejora Nusantara") -> PT. Indo Makmur Sentosa | D9: Qualified | E9: Managed Network | F9: Dedicated Network Service | G9: AM002 | H9: {=XLOOKUP(G:G,'Account Manager Data'!A:A,'Account Manager Data'!B:B,0)} -> Dedi Kurniawan | I9: {=XLOOKUP($G:$G,'Account Manager Data'!$A:$A,'Account Manager Data'!C:C)} -> Kalimantan | J9: 7902204 | K9: 4324843 | L9: 2618601 | M9: 8685348 | N9: 5869549 | O9: 14965106 | P9: 8492410 | Q9: 2352252 | R9: 0 | S9: 14061399 | T9: 18896236 | U9: 0 | V9: {=XLOOKUP(A:A,'Raw Revenue'!A:A,'Raw Revenue'!B:B,0)} -> 0 | W9: {=XLOOKUP(A:A,'Raw Revenue'!C:C,'Raw Revenue'!D:D,0)} -> 0 | X9: {=XLOOKUP(A:A,'Raw Revenue'!E:E,'Raw Revenue'!F:F,0)} -> 0 | Y9: {=XLOOKUP(A:A,'Raw Revenue'!G:G,'Raw Revenue'!H:H,0)} -> 0 | Z9: {=XLOOKUP(A:A,'Raw Revenue'!I:I,'Raw Revenue'!J:J,0)} -> 0 | AA9: {=XLOOKUP(A:A,'Raw Revenue'!K:K,'Raw Revenue'!L:L,0)} -> 0 | AB9: {=XLOOKUP(A:A,'Raw Revenue'!M:M,'Raw Revenue'!N:N,0)} -> 0 | AC9: 0 | AD9: 0 | AE9: 0 | AF9: 0 | AG9: 0
A10: PRJ00009 | B10: CL00009 | C10: =CHOOSE(MOD(ROW()-2, 20)+1, "PT. Maju Jaya", "CV. Sumber Makmur", "PT. Teknologi Nusantara", "PT. Bakti Indonesia", "CV. Amanah Sejahtera", "PT. Digital Solusi Pratama", "PT. Global Niaga Abadi", "PT. Indo Makmur Sentosa", "PT. Citra Mandiri Utama", "PT. Sinar Dunia Baru", "CV. Karya Utama Mandiri", "PT. Pratama Jaya Sentosa", "PT. Abadi Selamanya Jaya", "PT. Mandiri Sejahtera Bersama", "PT. Sejahtera Alam Indonesia", "PT. Indah Kargo Logistik", "PT. Berkah Alam Semesta", "PT. Cahaya Baru Indonesia", "PT. Mentari Pagi Sejahtera", "PT. Bintang Kejora Nusantara") -> PT. Citra Mandiri Utama | D10: Prospect | E10: Managed Network | F10: SD-WAN Enterprise | G10: AM009 | H10: {=XLOOKUP(G:G,'Account Manager Data'!A:A,'Account Manager Data'!B:B,0)} -> Teguh Wijaya | I10: {=XLOOKUP($G:$G,'Account Manager Data'!$A:$A,'Account Manager Data'!C:C)} -> Sulawesi | J10: 982441 | K10: 4733715 | L10: 4654353 | M10: 0 | N10: 6681782 | O10: 10384501 | P10: 0 | Q10: 1276070 | R10: 256764 | S10: 10545867 | T10: 4972907 | U10: 4664936 | V10: {=XLOOKUP(A:A,'Raw Revenue'!A:A,'Raw Revenue'!B:B,0)} -> 0 | W10: {=XLOOKUP(A:A,'Raw Revenue'!C:C,'Raw Revenue'!D:D,0)} -> 0 | X10: {=XLOOKUP(A:A,'Raw Revenue'!E:E,'Raw Revenue'!F:F,0)} -> 0 | Y10: {=XLOOKUP(A:A,'Raw Revenue'!G:G,'Raw Revenue'!H:H,0)} -> 0 | Z10: {=XLOOKUP(A:A,'Raw Revenue'!I:I,'Raw Revenue'!J:J,0)} -> 0 | AA10: {=XLOOKUP(A:A,'Raw Revenue'!K:K,'Raw Revenue'!L:L,0)} -> 0 | AB10: {=XLOOKUP(A:A,'Raw Revenue'!M:M,'Raw Revenue'!N:N,0)} -> 0 | AC10: 0 | AD10: 0 | AE10: 0 | AF10: 0 | AG10: 0
A11: PRJ00010 | B11: CL00010 | C11: =CHOOSE(MOD(ROW()-2, 20)+1, "PT. Maju Jaya", "CV. Sumber Makmur", "PT. Teknologi Nusantara", "PT. Bakti Indonesia", "CV. Amanah Sejahtera", "PT. Digital Solusi Pratama", "PT. Global Niaga Abadi", "PT. Indo Makmur Sentosa", "PT. Citra Mandiri Utama", "PT. Sinar Dunia Baru", "CV. Karya Utama Mandiri", "PT. Pratama Jaya Sentosa", "PT. Abadi Selamanya Jaya", "PT. Mandiri Sejahtera Bersama", "PT. Sejahtera Alam Indonesia", "PT. Indah Kargo Logistik", "PT. Berkah Alam Semesta", "PT. Cahaya Baru Indonesia", "PT. Mentari Pagi Sejahtera", "PT. Bintang Kejora Nusantara") -> PT. Sinar Dunia Baru | D11: Closed Lost | E11: Cyber Security | F11: SOC Monitoring | G11: AM004 | H11: {=XLOOKUP(G:G,'Account Manager Data'!A:A,'Account Manager Data'!B:B,0)} -> Eko Prasetyo | I11: {=XLOOKUP($G:$G,'Account Manager Data'!$A:$A,'Account Manager Data'!C:C)} -> Papua | J11: 6409402 | K11: 3847942 | L11: 10806210 | M11: 3183351 | N11: 0 | O11: 4699677 | P11: 9405758 | Q11: 8999847 | R11: 11060610 | S11: 16187701 | T11: 1851791 | U11: 7555624 | V11: {=XLOOKUP(A:A,'Raw Revenue'!A:A,'Raw Revenue'!B:B,0)} -> 0 | W11: {=XLOOKUP(A:A,'Raw Revenue'!C:C,'Raw Revenue'!D:D,0)} -> 0 | X11: {=XLOOKUP(A:A,'Raw Revenue'!E:E,'Raw Revenue'!F:F,0)} -> 0 | Y11: {=XLOOKUP(A:A,'Raw Revenue'!G:G,'Raw Revenue'!H:H,0)} -> 0 | Z11: {=XLOOKUP(A:A,'Raw Revenue'!I:I,'Raw Revenue'!J:J,0)} -> 0 | AA11: {=XLOOKUP(A:A,'Raw Revenue'!K:K,'Raw Revenue'!L:L,0)} -> 0 | AB11: {=XLOOKUP(A:A,'Raw Revenue'!M:M,'Raw Revenue'!N:N,0)} -> 0 | AC11: 0 | AD11: 0 | AE11: 0 | AF11: 0 | AG11: 0
A12: PRJ00011 | B12: CL00011 | C12: =CHOOSE(MOD(ROW()-2, 20)+1, "PT. Maju Jaya", "CV. Sumber Makmur", "PT. Teknologi Nusantara", "PT. Bakti Indonesia", "CV. Amanah Sejahtera", "PT. Digital Solusi Pratama", "PT. Global Niaga Abadi", "PT. Indo Makmur Sentosa", "PT. Citra Mandiri Utama", "PT. Sinar Dunia Baru", "CV. Karya Utama Mandiri", "PT. Pratama Jaya Sentosa", "PT. Abadi Selamanya Jaya", "PT. Mandiri Sejahtera Bersama", "PT. Sejahtera Alam Indonesia", "PT. Indah Kargo Logistik", "PT. Berkah Alam Semesta", "PT. Cahaya Baru Indonesia", "PT. Mentari Pagi Sejahtera", "PT. Bintang Kejora Nusantara") -> CV. Karya Utama Mandiri | D12: Prospect | E12: Cloud Services | F12: Nexa Cloud Basic | G12: AM007 | H12: {=XLOOKUP(G:G,'Account Manager Data'!A:A,'Account Manager Data'!B:B,0)} -> Yusuf Hidayat | I12: {=XLOOKUP($G:$G,'Account Manager Data'!$A:$A,'Account Manager Data'!C:C)} -> Sumatera | J12: 4823795 | K12: 154947 | L12: 3183954 | M12: 10934751 | N12: 9207038 | O12: 11357462 | P12: 165191 | Q12: 10893205 | R12: 10424593 | S12: 0 | T12: 7717241 | U12: 18979294 | V12: {=XLOOKUP(A:A,'Raw Revenue'!A:A,'Raw Revenue'!B:B,0)} -> 0 | W12: {=XLOOKUP(A:A,'Raw Revenue'!C:C,'Raw Revenue'!D:D,0)} -> 0 | X12: {=XLOOKUP(A:A,'Raw Revenue'!E:E,'Raw Revenue'!F:F,0)} -> 0 | Y12: {=XLOOKUP(A:A,'Raw Revenue'!G:G,'Raw Revenue'!H:H,0)} -> 0 | Z12: {=XLOOKUP(A:A,'Raw Revenue'!I:I,'Raw Revenue'!J:J,0)} -> 0 | AA12: {=XLOOKUP(A:A,'Raw Revenue'!K:K,'Raw Revenue'!L:L,0)} -> 0 | AB12: {=XLOOKUP(A:A,'Raw Revenue'!M:M,'Raw Revenue'!N:N,0)} -> 0 | AC12: 0 | AD12: 0 | AE12: 0 | AF12: 0 | AG12: 0
A13: PRJ00012 | B13: CL00012 | C13: =CHOOSE(MOD(ROW()-2, 20)+1, "PT. Maju Jaya", "CV. Sumber Makmur", "PT. Teknologi Nusantara", "PT. Bakti Indonesia", "CV. Amanah Sejahtera", "PT. Digital Solusi Pratama", "PT. Global Niaga Abadi", "PT. Indo Makmur Sentosa", "PT. Citra Mandiri Utama", "PT. Sinar Dunia Baru", "CV. Karya Utama Mandiri", "PT. Pratama Jaya Sentosa", "PT. Abadi Selamanya Jaya", "PT. Mandiri Sejahtera Bersama", "PT. Sejahtera Alam Indonesia", "PT. Indah Kargo Logistik", "PT. Berkah Alam Semesta", "PT. Cahaya Baru Indonesia", "PT. Mentari Pagi Sejahtera", "PT. Bintang Kejora Nusantara") -> PT. Pratama Jaya Sentosa | D13: Negotiation | E13: Managed Network | F13: SD-WAN Enterprise | G13: AM006 | H13: {=XLOOKUP(G:G,'Account Manager Data'!A:A,'Account Manager Data'!B:B,0)} -> Hendra Gunawan | I13: {=XLOOKUP($G:$G,'Account Manager Data'!$A:$A,'Account Manager Data'!C:C)} -> Kalimantan | J13: 8045081 | K13: 7998027 | L13: 7543878 | M13: 6422080 | N13: 11437900 | O13: 4705504 | P13: 10019906 | Q13: 15614123 | R13: 0 | S13: 11574329 | T13: 7669399 | U13: 11161020 | V13: {=XLOOKUP(A:A,'Raw Revenue'!A:A,'Raw Revenue'!B:B,0)} -> 0 | W13: {=XLOOKUP(A:A,'Raw Revenue'!C:C,'Raw Revenue'!D:D,0)} -> 0 | X13: {=XLOOKUP(A:A,'Raw Revenue'!E:E,'Raw Revenue'!F:F,0)} -> 0 | Y13: {=XLOOKUP(A:A,'Raw Revenue'!G:G,'Raw Revenue'!H:H,0)} -> 0 | Z13: {=XLOOKUP(A:A,'Raw Revenue'!I:I,'Raw Revenue'!J:J,0)} -> 0 | AA13: {=XLOOKUP(A:A,'Raw Revenue'!K:K,'Raw Revenue'!L:L,0)} -> 0 | AB13: {=XLOOKUP(A:A,'Raw Revenue'!M:M,'Raw Revenue'!N:N,0)} -> 0 | AC13: 0 | AD13: 0 | AE13: 0 | AF13: 0 | AG13: 0
... A1001: PRJ01000 | B1001: CL01000 | C1001: =CHOOSE(MOD(ROW()-2, 20)+1, "PT. Maju Jaya", "CV. Sumber Makmur", "PT. Teknologi Nusantara", "PT. Bakti Indonesia", "CV. Amanah Sejahtera", "PT. Digital Solusi Pratama", "PT. Global Niaga Abadi", "PT. Indo Makmur Sentosa", "PT. Citra Mandiri Utama", "PT. Sinar Dunia Baru", "CV. Karya Utama Mandiri", "PT. Pratama Jaya Sentosa", "PT. Abadi Selamanya Jaya", "PT. Mandiri Sejahtera Bersama", "PT. Sejahtera Alam Indonesia", "PT. Indah Kargo Logistik", "PT. Berkah Alam Semesta", "PT. Cahaya Baru Indonesia", "PT. Mentari Pagi Sejahtera", "PT. Bintang Kejora Nusantara") -> PT. Bintang Kejora Nusantara | D1001: Closed Won | E1001: Managed Network | F1001: Dedicated Network Service | G1001: AM005 | H1001: {=XLOOKUP(G:G,'Account Manager Data'!A:A,'Account Manager Data'!B:B,0)} -> Fajar Ramadhan | I1001: {=XLOOKUP($G:$G,'Account Manager Data'!$A:$A,'Account Manager Data'!C:C)} -> Sulawesi | J1001: 3755216 | K1001: 3796453 | L1001: 1411997 | M1001: 5112589 | N1001: 4717857 | O1001: 15062079 | P1001: 8861163 | Q1001: 4043144 | R1001: 2939086 | S1001: 11405497 | T1001: 12370397 | U1001: 9220153 | V1001: {=XLOOKUP(A:A,'Raw Revenue'!A:A,'Raw Revenue'!B:B,0)} -> 2227843 | W1001: {=XLOOKUP(A:A,'Raw Revenue'!C:C,'Raw Revenue'!D:D,0)} -> 2227843 | X1001: {=XLOOKUP(A:A,'Raw Revenue'!E:E,'Raw Revenue'!F:F,0)} -> 4455685.9 | Y1001: {=XLOOKUP(A:A,'Raw Revenue'!G:G,'Raw Revenue'!H:H,0)} -> 3638810.2 | Z1001: {=XLOOKUP(A:A,'Raw Revenue'!I:I,'Raw Revenue'!J:J,0)} -> 3267503 | AA1001: {=XLOOKUP(A:A,'Raw Revenue'!K:K,'Raw Revenue'!L:L,0)} -> 8354411.1 | AB1001: {=XLOOKUP(A:A,'Raw Revenue'!M:M,'Raw Revenue'!N:N,0)} -> 7686058.2 | AC1001: 0 | AD1001: 0 | AE1001: 0 | AF1001: 0 | AG1001: 0
A1002: 0 | B1002: 0 | C1002: 0 | D1002: 0 | E1002: 0 | F1002: 0 | G1002: 0 | H1002: {=XLOOKUP(G:G,'Account Manager Data'!A:A,'Account Manager Data'!B:B,0)} -> 0 | I1002: 0 | J1002: 0 | K1002: 0 | L1002: 0 | M1002: 0 | N1002: 0 | O1002: 0 | P1002: 0 | Q1002: 0 | R1002: 0 | S1002: 0 | T1002: 0 | U1002: 0 | V1002: 0 | W1002: 0 | X1002: 0 | Y1002: 0 | Z1002: 0 | AA1002: 0 | AB1002: 0 | AC1002: 0 | AD1002: 0 | AE1002: 0 | AF1002: 0 | AG1002: 0

Sheet AM 
